Workbook

Sheet Historical_Financials
B1: ITC Limited - Historical Financials
P2: (₹ Cr)
B3: Year | C3: Revenue | D3: EBIT | E3: Depreciation | F3: EBITDA | G3: PAT | H3: Adjusted PAT (Normalized) | I3: CFO | J3: CapEx (Reported / Proxy) | K3: CapEx (Estd) | L3: Change in Working Capital (Estd) | M3: FCFF | N3: CFO/FCFF | O3: EBITDA Margin | P3: EBIT Margin
B4: 2021 | C4: 49257.45 | D4: 17064.78 | E4: 1645.59 | F4: =D4+E4 -> 18710.37 | G4: 13161.19 | H4: =G4 -> 13161.19 | I4: 12526.97 | J4: 3000 | K4: =C4*3% -> 1477.7235 | L4: =C4*2% -> 985.149 | M4: =(D4 * 0.75) + E4 - K4 - L4 -> 11981.302 | N4: =I4/M4 -> 1.0455433 | O4: =F4/C4 -> 0.37984853 | P4: =D4/C4 -> 0.34644059
B5: 2022 | C5: 60644.54 | D5: 20623.15 | E5: 1732.41 | F5: =D5+E5 -> 22355.56 | G5: 15242.66 | H5: =G5 -> 15242.66 | I5: 15775.51 | J5: 2238.49 | K5: =C5*3% -> 1819.3362 | L5: =C5*2% -> 1212.8908 | M5: =(D5 * 0.75) + E5 - K5 - L5 -> 14167.546 | N5: =I5/M5 -> 1.1134963 | O5: =F5/C5 -> 0.36863269 | P5: =D5/C5 -> 0.34006606
B6: 2023 | C6: 70919.03 | D6: 25704.26 | E6: 1809.01 | F6: =D6+E6 -> 27513.27 | G6: 19191.66 | H6: =G6 -> 19191.66 | I6: 18877.55 | J6: 5732.29 | K6: =C6*3% -> 2127.5709 | L6: =C6*2% -> 1418.3806 | M6: =(D6 * 0.75) + E6 - K6 - L6 -> 17541.253 | N6: =I6/M6 -> 1.0761802 | O6: =F6/C6 -> 0.38795328 | P6: =D6/C6 -> 0.36244517
B7: 2024 | C7: 67931.94 | D7: 25187.53 | E7: 1518.05 | F7: =D7+E7 -> 26705.58 | G7: 20458.78 | H7: =G7 -> 20458.78 | I7: 17178.86 | J7: 2000 | K7: =C7*3% -> 2037.9582 | L7: =C7*2% -> 1358.6388 | M7: =(D7 * 0.75) + E7 - K7 - L7 -> 17012.1 | N7: =I7/M7 -> 1.0098024 | O7: =F7/C7 -> 0.39312259 | P7: =D7/C7 -> 0.37077596
B8: 2025 | C8: 75323.34 | D8: 25839.45 | E8: 1646.32 | F8: =D8+E8 -> 27485.77 | G8: 34746.63 | H8: 19600 | I8: 17627.04 | J8: 563.84 | K8: =C8*3% -> 2259.7002 | L8: =C8*2% -> 1506.4668 | M8: =(D8 * 0.75) + E8 - K8 - L8 -> 17259.741 | N8: =I8/M8 -> 1.0212807 | O8: =F8/C8 -> 0.36490376 | P8: =D8/C8 -> 0.34304706
C11: PAT Reconciliation Table | G11: (₹ Cr)
C12: Items | D12: FY2025 | E12: Source/Note
C13: Reported PAT | D13: =G8 -> 34746.63 | E13: As per Annual Report / Income Statement
C14: (-) One-time Demerger Gain | D14: 15147 | E14: Exceptional item (Hotel demerger gain)
C15: Adjusted PAT (Normalized) | D15: =D13-D14 -> 19599.63 | E15: Base used for Valuation
C18: Notes:
C19: 1. FY25 PAT normalized by removing ~₹15,150 Cr hotel demerger gain
C20: 2. Adjusted PAT used for forecasting and valuation consistency
C21: 3.CapEx normalized at ~3% of revenue to smooth volatile reported investment flows
C22: 4. Working capital modeled at ~2% of revenue for steady-state operations
C23: 5. EBITDA is included for margin trend validation and for potential use in relative valuation (EV/EBITDA benchmarking)
C24: 6. CFO/FCFF ratio near ~1.0x supports cash flow quality and FCFF quality
C25: 7. FCFF calculated using EBIT × (1 - Tax Rate) + D&A - CapEx - ΔWC

Sheet Segment_Analysis
B1: ITC Limited - Segment Analysis (FY2024-FY2025)
I2: (₹ Cr)
B3: Segment | C3: Revenue 2025 | D3: EBIT 2025 | E3: Revenue 2024 | F3: EBIT 2024 | G3: Margin 2025 | H3: Revenue Growth | I3: Profit Contribution (%)
B4: Cigarettes | C4: 32631.27 | D4: 20024.87 | E4: 30596.59 | F4: 19089.17 | G4: =D4/C4 -> 0.61367118 | H4: =(C4-E4)/E4 -> 0.066500221 | I4: =D4/$D$11 -> 0.77498416
B5: FMCG | C5: 21981.57 | D5: 1579.66 | E5: 20966.83 | F5: 1778.55 | G5: =D5/C5 -> 0.071862929 | H5: =(C5-E5)/E5 -> 0.048397397 | I5: =D5/$D$11 -> 0.061134553
B6: Agri | C6: 19753.8 | D6: 1478.03 | E6: 15791.83 | F6: 1254.43 | G6: =D6/C6 -> 0.074822566 | H6: =(C6-E6)/E6 -> 0.25088733 | I6: =D6/$D$11 -> 0.057201362
B7: Paperboards | C7: 8422.81 | D7: 911.49 | E7: 8344.4 | F7: 1377.6 | G7: =D7/C7 -> 0.10821685 | H7: =(C7-E7)/E7 -> 0.0093967212 | I7: =D7/$D$11 -> 0.03527565
B8: Others | C8: 167.37 | D8: 64.02 | E8: 145.26 | F8: 53.09 | G8: =D8/C8 -> 0.38250583 | H8: =(C8-E8)/E8 -> 0.15220983 | I8: =D8/$D$11 -> 0.0024776434
B10: (+) Unallocated Corporate Income / Adjustments | C10: 0 | D10: 1781 | E10: 0 | F10: 0 | I10: =D10/$D$11 -> 0.068926629
B11: Total | C11: =SUM(C4:C8) -> 82956.82 | D11: =SUM(D4:D10) -> 25839.07 | E11: =SUM(E4:E8) -> 75844.91 | F11: =SUM(F4:F8) -> 23552.84 | I11: =SUM(I4:I10) -> 1
B13: Working Note: | D13: (₹ Cr)
B14: Total Segment Revenue (Gross): | D14: =C11 -> 82956.82
B15: (-) Inter-segment / Excise Adjustments: | D15: 7634
B16: Consolidated Net Revenue: | D16: =D14-D15 -> 75322.82
B18: Key Segment Insights: | C18: 1. Profit Dependency
C19: Cigarettes contribute around 77.5% of total EBIT, indicating heavy dependence on a single high margin segment.
C20: 2. Growth Driver Strategy
C21: FMCG is the primary long-term growth driver but currently contributes only ~6-7% of EBIT due to low margins.
C22: 3. Margin Structure
C23: Cigarettes have extremely high margins (~60%), while other segments operate in the 7 to 11% range.
C24: 4. Strategic Shift
C25: ITC is gradually shifting towards FMCG for growth, which may lead to margin compression over time.
C26: 5. Risk Concentration
C27: Heavy reliance on cigarettes exposes ITC to regulatory and taxation risks.
C28: 6. Valuation Disconnect Insight
C29: Despite FMCG expansion, ITC’s valuation remains anchored to cigarettes due to disproportionate profit contribution and superior margins.
B30: Notes: | C30: 1. Segment revenue shown on gross basis; consolidated revenue shown net of eliminations
C31: 2. Forecasting uses consolidated revenue from financial statements
C32: 3. "Others" segment excluded from valuation relevance due to immaterial contribution
C33: 4. FY25 used as base year reference for segment forecasting

Sheet Assumptions
A1: ITC Limited - Assumptions
B4: 1. Revenue Growth Assumptions | H4: Notes:
B5: Segment | C5: Growth % (Base Case) | H5: 1. Revenue growth based on segment level analysis
B6: Cigarettes | C6: 0.05 | H6: 2. FMCG margins expected to expand from ~8% to ~11.5% over forecast period, driven by operating leverage and premiumization
B7: FMCG | C7: 0.11 | H7: 3. Capex assumed at 3% based on historical average (conservative)
B8: Agri | C8: 0.07 | H8: 4. Tax rate normalized at 25%
B9: Paperboards | C9: 0.04 | H9: 5. EBIT used as the base for FCFF projections; Adjusted PAT used for bottom-line reconciliation and EPS trend analysis
H10: 6. Working capital assumed at 2% of revenue to normalize Agri-segment seasonality
B12: 2. Margin Assumptions
B13: Segment | C13: EBIT Margin
B14: Cigarettes | C14: 0.62
B15: FMCG | C15: =C43 -> 0.078
B16: Agri | C16: 0.07
B17: Paperboards | C17: 0.11
B20: 3. Cost of Capital Assumptions
B21: Item | C21: Value
B22: Risk Free Rate | C22: 0.07
B23: Equity Risk Premium | C23: 0.065
B24: Levered Beta | C24: 0.75
B25: Cost of Equity (Ke) | C25: =C22+C24*C23 -> 0.11875
B26: Cost of Debt (Pre-tax) (Kd) | C26: 0.08
B27: Tax Rate | C27: 0.25
B28: Debt % | C28: 0.1
B29: Equity % | C29: 0.9
B30: WACC | C30: =(C29*C25)+(C28*C26*(1-C27)) -> 0.112875
B33: 4. Other Assumptions
B34: Item | C34: Value
B35: Depreciation (% of Revenue) | C35: 0.022
B36: Capex (% of Revenue) | C36: 0.03
B37: Working Capital (% of Revenue) | C37: 0.02
B38: Terminal Growth (g) | C38: 0.04
B41: 5. FMCG Margin Trend
B42: Year | C42: FMCG Margin
B43: 2026 | C43: 0.078
B44: 2027 | C44: 0.088
B45: 2028 | C45: 0.098
B46: 2029 | C46: 0.108
B47: 2030 | C47: 0.115
B50: 6. Case Assumptions
B51: Item | C51: Bear Case | D51: Bull Case
...

Sheet Forecast_Model
B1: ITC Limited - Financial Forecast Model
J4: Scaling Factor (Gross → Net) | M4: =75323/82957 -> 0.90797642
B5: Segment Revenue Forecast | H5: (₹ Cr)
B6: Segment | C6: 2025 | D6: 2026 | E6: 2027 | F6: 2028 | G6: 2029 | H6: 2030 | J6: Notes:
B7: Cigarettes | C7: =ROUND(Segment_Analysis!$C4*Forecast_Model!$M$4, 0) -> 29628 | D7: =ROUND(C7*(1+Assumptions!$C6),0) -> 31109 | E7: =ROUND(D7*(1+Assumptions!$C6),0) -> 32664 | F7: =ROUND(E7*(1+Assumptions!$C6),0) -> 34297 | G7: =ROUND(F7*(1+Assumptions!$C6),0) -> 36012 | H7: =ROUND(G7*(1+Assumptions!$C6),0) -> 37813 | J7: 1. Revenue forecast based on segment-level growth assumptions
B8: FMCG | C8: =ROUND(Segment_Analysis!$C5*Forecast_Model!$M$4, 0) -> 19959 | D8: =ROUND(C8*(1+Assumptions!$C7),0) -> 22154 | E8: =ROUND(D8*(1+Assumptions!$C7),0) -> 24591 | F8: =ROUND(E8*(1+Assumptions!$C7),0) -> 27296 | G8: =ROUND(F8*(1+Assumptions!$C7),0) -> 30299 | H8: =ROUND(G8*(1+Assumptions!C7),0) -> 33632 | J8: 2. EBIT derived using segment-level margin assumptions
B9: Agri | C9: =ROUND(Segment_Analysis!$C6*Forecast_Model!$M$4, 0) -> 17936 | D9: =ROUND(C9*(1+Assumptions!$C8),0) -> 19192 | E9: =ROUND(D9*(1+Assumptions!$C8),0) -> 20535 | F9: =ROUND(E9*(1+Assumptions!$C8),0) -> 21972 | G9: =ROUND(F9*(1+Assumptions!$C8),0) -> 23510 | H9: =ROUND(G9*(1+Assumptions!C8),0) -> 25156 | J9: 3. Depreciation assumed at ~2.2% of revenue (proxy)
B10: Paperboards | C10: =ROUND(Segment_Analysis!$C7*Forecast_Model!$M$4, 0) -> 7648 | D10: =ROUND(C10*(1+Assumptions!$C9),0) -> 7954 | E10: =ROUND(D10*(1+Assumptions!$C9),0) -> 8272 | F10: =ROUND(E10*(1+Assumptions!$C9),0) -> 8603 | G10: =ROUND(F10*(1+Assumptions!$C9),0) -> 8947 | H10: =ROUND(G10*(1+Assumptions!C9),0) -> 9305 | J10: 4. CapEx normalized at 3% of revenue for forecast; base year adjusted for consistency
B11: Others | C11: =ROUND(Segment_Analysis!$C8*Forecast_Model!$M$4, 0) -> 152 | D11: =ROUND(C11*(1+Assumptions!$C10),0) -> 152 | E11: =ROUND(D11*(1+Assumptions!$C10),0) -> 152 | F11: =ROUND(E11*(1+Assumptions!$C10),0) -> 152 | G11: =ROUND(F11*(1+Assumptions!$C10),0) -> 152 | H11: =ROUND(G11*(1+Assumptions!C10),0) -> 152 | J11: 5. Segment revenues modeled on gross basis; scaling factor applied for net revenue reconciliation
B12: Total | C12: =SUM(C7:C11) -> 75323 | D12: =SUM(D7:D11) -> 80561 | E12: =SUM(E7:E11) -> 86214 | F12: =SUM(F7:F11) -> 92320 | G12: =SUM(G7:G11) -> 98920 | H12: =SUM(H7:H11) -> 106058 | J12: 6. FCFF calculated as NOPAT + Depreciation – CapEx – Change in WC
J13: 7. "Others" segment assumed flat due to immaterial contribution
J14: 8. Unallocated Corporate & Other Income included for EBIT reconciliation
B15: Segment EBIT Forecast | H15: (₹ Cr) | J15: 9. 2026–2030 forecasts focus on core operating EBIT
B16: Segment | C16: 2025 | D16: 2026 | E16: 2027 | F16: 2028 | G16: 2029 | H16: 2030 | J16: 10. FY25 EBIT includes non-operating gains; FY26 FCFF reflects normalized operations
B17: Cigarettes | C17: =ROUND(C7*Assumptions!$C$14, 0) -> 18369 | D17: =ROUND(D7*Assumptions!$C$14, 0) -> 19288 | E17: =ROUND(E7*Assumptions!$C$14, 0) -> 20252 | F17: =ROUND(F7*Assumptions!$C$14, 0) -> 21264 | G17: =ROUND(G7*Assumptions!$C$14, 0) -> 22327 | H17: =ROUND(H7*Assumptions!$C$14, 0) -> 23444
B18: FMCG | C18: =ROUND(C8*Assumptions!$C43, 0) -> 1557 | D18: =ROUND(D8*Assumptions!C43, 0) -> 1728 | E18: =ROUND(E8*Assumptions!$C44, 0) -> 2164 | F18: =ROUND(F8*Assumptions!$C45, 0) -> 2675 | G18: =ROUND(G8*Assumptions!$C46, 0) -> 3272 | H18: =ROUND(H8*Assumptions!$C47, 0) -> 3868
B19: Agri | C19: =ROUND(Forecast_Model!C9*Assumptions!$C$16, 0) -> 1256 | D19: =ROUND(Forecast_Model!D9*Assumptions!$C$16, 0) -> 1343 | E19: =ROUND(Forecast_Model!E9*Assumptions!$C$16, 0) -> 1437 | F19: =ROUND(Forecast_Model!F9*Assumptions!$C$16, 0) -> 1538 | G19: =ROUND(Forecast_Model!G9*Assumptions!$C$16, 0) -> 1646 | H19: =ROUND(Forecast_Model!H9*Assumptions!$C$16, 0) -> 1761
B20: Paperboards | C20: =ROUND(C10*Assumptions!$C$17,0) -> 841 | D20: =ROUND(D10*Assumptions!$C$17,0) -> 875 | E20: =ROUND(E10*Assumptions!$C$17,0) -> 910 | F20: =ROUND(F10*Assumptions!$C$17,0) -> 946 | G20: =ROUND(G10*Assumptions!$C$17,0) -> 984 | H20: =ROUND(H10*Assumptions!$C$17,0) -> 1024
B21: Others | C21: =ROUND(C11*35%,0) -> 53 | D21: =ROUND(D11*35%,0) -> 53 | E21: =ROUND(E11*35%,0) -> 53 | F21: =ROUND(F11*35%,0) -> 53 | G21: =ROUND(G11*35%,0) -> 53 | H21: =ROUND(H11*35%,0) -> 53
B22: Unallocated Corporate & Other Income | C22: 3763 | D22: =C22*1.04 -> 3913.52 | E22: =D22*1.04 -> 4070.0608 | F22: =E22*1.04 -> 4232.8632 | G22: =F22*1.04 -> 4402.1778 | H22: =G22*1.04 -> 4578.2649
B23: Total EBIT | C23: =SUM(C17:C22) -> 25839 | D23: =SUM(D17:D22) -> 27200.52 | E23: =SUM(E17:E22) -> 28886.061 | F23: =SUM(F17:F22) -> 30708.863 | G23: =SUM(G17:G22) -> 32684.178 | H23: =SUM(H17:H22) -> 34728.265
B25: EBIT Margin | C25: =C23/C12 -> 0.34304263 | D25: =D23/D12 -> 0.33763881 | E25: =E23/E12 -> 0.3350507 | F25: =F23/F12 -> 0.332635 | G25: =G23/G12 -> 0.33041021 | H25: =H23/H12 -> 0.32744597
B28: FCFF Forecast | H28: (₹ Cr)
B29: Type | C29: Base Year | D29: Forecast | E29: Forecast | F29: Forecast | G29: Forecast | H29: Forecast
B30: Year | C30: 2025 | D30: 2026 | E30: 2027 | F30: 2028 | G30: 2029 | H30: 2030
B31: Total Revenue | C31: =Historical_Financials!C8 -> 75323.34 | D31: =D12 -> 80561 | E31: =E12 -> 86214 | F31: =F12 -> 92320 | G31: =G12 -> 98920 | H31: =H12 -> 106058
B32: Total EBIT | C32: =Historical_Financials!D8 -> 25839.45 | D32: =D23 -> 27200.52 | E32: =E23 -> 28886.061 | F32: =F23 -> 30708.863 | G32: =G23 -> 32684.178 | H32: =H23 -> 34728.265
B33: NOPAT | C33: =C32*(1-Assumptions!C27) -> 19379.588 | D33: =D32*(1-Assumptions!C27) -> 20400.39 | E33: =E32*(1-Assumptions!C27) -> 21664.546 | F33: =F32*(1-Assumptions!C27) -> 23031.647 | G33: =G32*(1-Assumptions!C27) -> 24513.133 | H33: =H32*(1-Assumptions!C27) -> 26046.199
B34: (+) Depreciation | C34: =Historical_Financials!E8 -> 1646.32 | D34: =D31*Assumptions!$C$35 -> 1772.342 | E34: =E31*Assumptions!$C$35 -> 1896.708 | F34: =F31*Assumptions!$C$35 -> 2031.04 | G34: =G31*Assumptions!$C$35 -> 2176.24 | H34: =H31*Assumptions!$C$35 -> 2333.276
B35: (-) CapEx | C35: =Historical_Financials!K8 -> 2259.7002 | D35: =D31*Assumptions!$C$36 -> 2416.83 | E35: =E31*Assumptions!$C$36 -> 2586.42 | F35: =F31*Assumptions!$C$36 -> 2769.6 | G35: =G31*Assumptions!$C$36 -> 2967.6 | H35: =H31*Assumptions!$C$36 -> 3181.74
B36: (-) Change in WC | C36: =Historical_Financials!L8 -> 1506.4668 | D36: =(D31-C31)*Assumptions!$C$37 -> 104.7532 | E36: =(E31-D31)*Assumptions!$C$37 -> 113.06 | F36: =(F31-E31)*Assumptions!$C$37 -> 122.12 | G36: =(G31-F31)*Assumptions!$C$37 -> 132 | H36: =(H31-G31)*Assumptions!$C$37 -> 142.76
B37: FCFF | C37: =ROUND(C33+C34-C35-C36,0) -> 17260 | D37: =ROUND(D33+D34-D35-D36,0) -> 19651 | E37: =ROUND(E33+E34-E35-E36,0) -> 20862 | F37: =ROUND(F33+F34-F35-F36,0) -> 22171 | G37: =ROUND(G33+G34-G35-G36,0) -> 23590 | H37: =ROUND(H33+H34-H35-H36,0) -> 25055

Sheet DCF
B1: ITC Limited - Discounted Cash Flow Valuation
B3: Cost of Capital | H3: Notes:
B4: Item | C4: Value | H4: 1. Valuation based on Free Cash Flow to Firm (FCFF) methodology.
B5: Risk-Free Rate | C5: =Assumptions!C22 -> 0.07 | H5: 2. Cost of Equity calculated using CAPM: Risk-Free Rate + Beta × Equity Risk Premium.
B6: Equity Risk Premium | C6: =Assumptions!C23 -> 0.065 | H6: 3. WACC used as discount rate, assuming 90% equity and 10% debt structure.
B7: Beta | C7: =Assumptions!C24 -> 0.75 | H7: 4. Terminal value calculated using Gordon Growth Model with a long-term growth rate of 4%.
B8: Cost of Equity | C8: =C5+C7*C6 -> 0.11875 | H8: 5. 50% haircut on illiquid investments; Cash/Current at face value.
B9: Cost of Debt | C9: =Assumptions!C26 -> 0.08 | H9: 6. Valuation is sensitive to changes in WACC and terminal growth, as shown in sensitivity analysis.
B10: Tax Rate | C10: =Assumptions!C27 -> 0.25 | H10: 7. Current Market Price (CMP) compared to intrinsic value to assess valuation gap.
B11: Debt % | C11: =Assumptions!C28 -> 0.1 | H11: 8. Discount factors are derived as 1 / (1 + WACC)^n to determine the present value of future cash flows.
B12: Equity % | C12: =Assumptions!C29 -> 0.9 | H12: 9. Minority interest deducted to isolate value attributable solely to ITC shareholders
B13: WACC | C13: =(C12 * C8) + (C11 * C9 * (1 - C10)) -> 0.112875
H14: Valuation Conclusion:
H15: Base case intrinsic value of ₹254.73 implies ~18% downside vs CMP of ₹311
B16: Discounted FCFF Table | E16: (₹ Cr) | H16: Bull case valuation reaches ~₹351; base case remains ~18% below CMP
B17: Year | C17: FCFF | D17: Discount Factor | E17: Pv of FCFF | H17: Current market valuation implies stronger growth and margin expectations
B18: 2026 | C18: =Forecast_Model!D$37 -> 19651 | D18: =1 / (1 + $C$13)^1 -> 0.89857351 | E18: =C18*D18 -> 17657.868 | H18: Verdict: Market pricing reflects optimistic long-term FMCG expectations
B19: 2027 | C19: =Forecast_Model!E$37 -> 20862 | D19: =1 / (1 + $C$13)^2 -> 0.80743436 | E19: =C19*D19 -> 16844.696
B20: 2028 | C20: =Forecast_Model!F$37 -> 22171 | D20: =1 / (1 + $C$13)^3 -> 0.72553913 | E20: =C20*D20 -> 16085.928
B21: 2029 | C21: =Forecast_Model!G$37 -> 23590 | D21: =1 / (1 + $C$13)^4 -> 0.65195025 | E21: =C21*D21 -> 15379.506
B22: 2030 | C22: =Forecast_Model!H$37 -> 25055 | D22: =1 / (1 + $C$13)^5 -> 0.58582523 | E22: =C22*D22 -> 14677.851
B25: Terminal Value Calculation | C25: (₹ Cr)
B26: Item | C26: Value
B27: FCFF (2030) | C27: =Forecast_Model!H37 -> 25055
B28: Terminal Growth (g) | C28: 0.04
B29: WACC | C29: =C13 -> 0.112875 | F29: Sensitivity Analysis (₹ per share)
B30: Terminal Value (2030) | C30: =C27*(1+C28)/(C29-C28) -> 357560.21 | I30: Terminal Growth →
B31: Discount Factor (2030) | C31: =D22 -> 0.58582523 | F31: Base Case | G31: =C50 -> 254.73454 | H31: 0.03 | I31: 0.04 | J31: 0.05
B32: PV of Terminal Value | C32: =C30*C31 -> 209467.79 | G32: 0.1 | H32: 272.47822 | I32: 304.99748 | J32: 350.52444
F33: WACC ↓ | G33: 0.11 | H33: 240.83059 | I33: 264.35294 | J33: 295.71607
B34: Enterprise Value | C34: =SUM(E18:E22)+C32 -> 290113.64 | G34: 0.12 | H34: 216.23091 | I34: 233.88137 | J34: 256.57482
B37: Equity Bridge | C37: (₹ Cr)
B38: Enterprise Value | C38: =C34 -> 290113.64
B39: (-) Debt | C39: 91
B40: (+) Cash | C40: 4012
B41: (+) Current Investments | C41: 16287
B42: (+) Non-current Investments (50% of 18,432) | C42: 9216
B43: (-) Minority Interest | C43: 368 | E43: Valuation Scenarios
B44: Equity Value | C44: =C38-C39+C40+C41+C42-C43 -> 319169.64 | E44: Bear Case | F44: =H34 -> 216.23091
E45: Base Case | F45: =G31 -> 254.73454
...

Sheet DCF (Formatted) 
B1: ITC Limited - DCF Valuation Summary
G2: (₹ Cr)
B3: I. UNLEVERED FREE CASH FLOW PROJECTION (₹ Cr)
C4: 2026 | D4: 2027 | E4: 2028 | F4: 2029 | G4: 2030
B5: Revenue | C5: =Forecast_Model!D$12 -> 80561 | D5: =Forecast_Model!E$12 -> 86214 | E5: =Forecast_Model!F$12 -> 92320 | F5: =Forecast_Model!G$12 -> 98920 | G5: =Forecast_Model!H$12 -> 106058
B6: EBIT | C6: =Forecast_Model!D$23 -> 27200.52 | D6: =Forecast_Model!E$23 -> 28886.061 | E6: =Forecast_Model!F$23 -> 30708.863 | F6: =Forecast_Model!G$23 -> 32684.178 | G6: =Forecast_Model!H$23 -> 34728.265
B7: NOPAT | C7: =Forecast_Model!D$33 -> 20400.39 | D7: =Forecast_Model!E$33 -> 21664.546 | E7: =Forecast_Model!F$33 -> 23031.647 | F7: =Forecast_Model!G$33 -> 24513.133 | G7: =Forecast_Model!H$33 -> 26046.199
B8: (+) Depreciation | C8: =Forecast_Model!D$34 -> 1772.342 | D8: =Forecast_Model!E$34 -> 1896.708 | E8: =Forecast_Model!F$34 -> 2031.04 | F8: =Forecast_Model!G$34 -> 2176.24 | G8: =Forecast_Model!H$34 -> 2333.276
B9: (-) CapEx | C9: =Forecast_Model!D$35 -> 2416.83 | D9: =Forecast_Model!E$35 -> 2586.42 | E9: =Forecast_Model!F$35 -> 2769.6 | F9: =Forecast_Model!G$35 -> 2967.6 | G9: =Forecast_Model!H$35 -> 3181.74
B10: (-) Change in WC | C10: =Forecast_Model!D$36 -> 104.7532 | D10: =Forecast_Model!E$36 -> 113.06 | E10: =Forecast_Model!F$36 -> 122.12 | F10: =Forecast_Model!G$36 -> 132 | G10: =Forecast_Model!H$36 -> 142.76
B11: FCFF | C11: =C7+C8-C9-C10 -> 19651.149 | D11: =D7+D8-D9-D10 -> 20861.774 | E11: =E7+E8-E9-E10 -> 22170.967 | F11: =F7+F8-F9-F10 -> 23589.773 | G11: =G7+G8-G9-G10 -> 25054.975
B12: Discount Factor | C12: =1/(1+$C$39)^(COLUMN()-COLUMN($C$12)+1) -> 0.89857351 | D12: =1/(1+$C$39)^(COLUMN()-COLUMN($C$12)+1) -> 0.80743436 | E12: =1/(1+$C$39)^(COLUMN()-COLUMN($C$12)+1) -> 0.72553913 | F12: =1/(1+$C$39)^(COLUMN()-COLUMN($C$12)+1) -> 0.65195025 | G12: =1/(1+$C$39)^(COLUMN()-COLUMN($C$12)+1) -> 0.58582523
B13: PV of FCFF | C13: =C11*C12 -> 17658.002 | D13: =D11*D12 -> 16844.513 | E13: =E11*E12 -> 16085.904 | F13: =F11*F12 -> 15379.359 | G13: =G11*G12 -> 14677.836
C15: (₹ Cr)
B16: II. VALUATION SUMMARY & EQUITY BRIDGE
B17: Sum of Pv of FCFF | C17: =SUM(C13:G13) -> 80645.614 | I17: IV. SENSITIVITY ANALYSIS
B18: Terminal Value (2030) | C18: =(G11*(1+Assumptions!C38)/(Assumptions!C30-Assumptions!C38)) -> 357559.84 | I18: Implied Share Price
B19: PV of Terminal Value | C19: =C18*G12 -> 209467.58 | J19: Terminal Growth Rate →
B20: Enterprise Value | C20: =SUM(C13:G13)+C19 -> 290113.19 | G20: Rounded Sensitivity Base | H20: =C28 -> 254.73418 | I20: 0.03 | J20: 0.04 | K20: 0.05
B21: (-) Total Debt | C21: 91 | H21: 0.1 | I21: =DCF!H32 -> 272.47822 | J21: =DCF!I32 -> 304.99748 | K21: =DCF!J32 -> 350.52444
B22: (+) Cash & Cash Equivalents | C22: 4012 | G22: WACC ↓ | H22: 0.11 | I22: =DCF!H33 -> 240.83059 | J22: =DCF!I33 -> 264.35294 | K22: =DCF!J33 -> 295.71607
B23: (+) Current Investments | C23: 16287 | H23: 0.12 | I23: =DCF!H34 -> 216.23091 | J23: =DCF!I34 -> 233.88137 | K23: =DCF!J34 -> 256.57482
B24: (+) Non-Current Inv. (50% Haircut) | C24: 9216
B25: (-) Minority Interest | C25: 368
B26: Equity Value | C26: =C20-C21+C22+C23+C24-C25 -> 319169.19
B27: Shares Outstanding | C27: 1252.95
B28: Intrinsic Value Per Share | C28: =C26/C27 -> 254.73418
B30: III. VALUATION ASSUMPTIONS | I30: V. OUTPUT
B31: Risk Free Rate | C31: 0.07 | I31: Intrinsic Value | J31: =C28 -> 254.73418
B32: Equity Risk Premium | C32: 0.065 | I32: CMP | J32: 311
B33: Beta | C33: 0.75 | I33: Upside/ Downside | J33: =(J31-J32)/J32 -> -0.18091904
B34: Cost of Equity (Ke) | C34: =C31+C33*C32 -> 0.11875
B35: Cost of Debt (Pre-tax) (Kd) | C35: 0.08
B36: Tax Rate | C36: 0.25
B37: Debt % | C37: 0.1
B38: Equity % | C38: 0.9
B39: WACC | C39: =(C38 * C34) + (C37 * C35 * (1-C36)) -> 0.112875
B40: Terminal Growth | C40: =Assumptions!C38 -> 0.04
B42: Conclusion:
B43: Base case value ₹254.73 vs CMP ₹311 → ~18% downside
...

Sheet Relative_Valuation
B1: ITC Limited - Relative Valuation Analysis
G3: (All values in ₹ Cr unless stated otherwise)
B4: Company | C4: CMP | D4: Market Cap | E4: Shares | F4: Debt | G4: Cash | H4: Revenue | I4: EBIT | J4: PAT | L4: Valuation Insight:
B5: ITC Ltd | C5: ='DCF (Formatted) '!J32 -> 311 | D5: 394553 | E5: ='DCF (Formatted) '!C27 -> 1252.95 | F5: ='DCF (Formatted) '!C21 -> 91 | G5: ='DCF (Formatted) '!C22 -> 4012 | H5: =Historical_Financials!C8 -> 75323.34 | I5: =Historical_Financials!D8 -> 25839.45 | J5: =Historical_Financials!H8 -> 19600 | L5: 1. ITC trades at ~20x P/E, below FMCG peers (~72x) but closer to tobacco peers (~24x)
B6: FMCG: | L6: 2. Market valuation continues to anchor primarily to the cigarette business
B7: HUL | C7: 2254 | D7: 528870 | E7: 234.64 | F7: 1 | G7: 7554 | H7: 63121 | I7: 14843 | J7: 10649 | L7: 3. FMCG scale and margins remain below premium FMCG peer benchmarks
B8: Tata Consumer | C8: 1147.7 | D8: 113265 | E8: 98.69 | F8: 1849 | G8: 2818 | H8: 17618 | I8: 2479 | J8: 1278 | L8: 4. Relative valuation suggests ITC is fairly priced relative to tobacco peers
B9: Britannia | C9: 5729 | D9: 137921 | E9: 24.07 | F9: 1225 | G9: 312 | H9: 17943 | I9: 3176 | J9: 2179 | L9: 5. DCF valuation (₹254.73) also indicates limited upside from current levels
B10: Nestle India | C10: 1459 | D10: 281264 | E10: 192.78 | F10: 753 | G10: 96 | H10: 20202 | I10: 4771 | J10: 3315 | L10: Notes:
B11: Tobacco: | L11: 1. EBIT sourced from Screener operating profit data
B12: Godfrey Phillips | C12: 2251 | D12: 35111 | E12: 15.6 | F12: 29 | G12: 30 | H12: 5611 | I12: 1177 | J12: 1072 | L12: 2. ITC PAT normalized to exclude hotel demerger gain
B13: VST Indsutries | C13: 258 | D13: 4389 | E13: 17.01 | F13: - | G13: 18 | H13: 1398 | I13: 279 | J13: 290 | L13: 3. Financials based on FY25 consolidated data
L14: 4. Tobacco benchmarks are more relevant due to higher profit contribution
B15: Relative Valuation Summery | L15: 5. Median multiples used to reduce outlier distortion
B16: Company | C16: EV | D16: P/E | E16: EV/EBIT
B17: ITC Ltd | C17: =D5+F5-G5 -> 390632 | D17: =D5/J5 -> 20.130255 | E17: =C17/I5 -> 15.117659 | L17: IMPLIED VALUATION (ITC):
B18: FMCG: | L18: 1. Using Tobacco Avg P/E: | O18: =C35*J5/E5 -> 374.55234
B19: HUL | C19: =D7+F7-G7 -> 521317 | D19: =D7/J7 -> 49.663818 | E19: =C19/I7 -> 35.122078 | L19: 2. Using FMCG Avg P/E: | O19: =C29*J5/E5 -> 1120.1698
B20: Tata Consumer | C20: =D8+F8-G8 -> 112296 | D20: =D8/J8 -> 88.626761 | E20: =C20/I8 -> 45.298911 | L20: FMCG-based multiples imply substantial upside, but current profitability does not support premium FMCG valuations.
B21: Britannia | C21: =D9+F9-G9 -> 138834 | D21: =D9/J9 -> 63.295548 | E21: =C21/I9 -> 43.713476 | L21: This reflects structural discounts due to tobacco exposure, regulatory risks, and lower FMCG margin profile.
B22: Nestle India | C22: =D10+F10-G10 -> 281921 | D22: =D10/J10 -> 84.845852 | E22: =C22/I10 -> 59.090547
B23: Tobacco:
B24: Godfrey Phillips | C24: =D12+F12-G12 -> 35110 | D24: =D12/J12 -> 32.752799 | E24: =C24/I12 -> 29.830076
B25: VST Indsutries | C25: =D13+0-G13 -> 4371 | D25: =D13/J13 -> 15.134483 | E25: =C25/I13 -> 15.666667
B27: Benchmark Statistics
B28: FMCG Benchmarks: | C28: Multiples (x)
B29: Avg P/E | C29: =AVERAGE(D19:D22) -> 71.607995
B30: Median P/E | C30: =MEDIAN(D19:D22) -> 74.0707
B31: Avg EV/EBIT | C31: =AVERAGE(E19:E22) -> 45.806253
B32: Median EV/EBIT | C32: =MEDIAN(E19:E22) -> 44.506193
B34: Tobacco Benchmarks: | C34: Multiples (x)
B35: Avg P/E | C35: =AVERAGE(D24:D25) -> 23.943641
B36: Median P/E | C36: =MEDIAN(D24:D25) -> 23.943641
B37: Avg EV/EBIT | C37: =AVERAGE(E24:E25) -> 22.748372
B38: Median EV/EBIT | C38: =MEDIAN(E24:E25) -> 22.748372

Sheet Summary
B2: ITC Limited – Investment Summary
B3: NSE: ITC | FMCG / Tobacco Conglomerate |
B4: CMP: ₹311 | Date: 4th May 2026 | Analyst: Prathamesh Rathod
B6: INVESTMENT THESIS | H6: KEY FINANCIALS | N6: (₹ Cr)
B7: 1. Cigarettes contribute ~78% of EBIT despite | H7: Metric | I7: FY23 | J7: FY24 | K7: FY25 | L7: FY26E | M7: FY27E | N7: FY28E
B8: 39% revenue share - profit concentration | H8: Revenue | I8: =Historical_Financials!C6 -> 70919.03 | J8: =Historical_Financials!C7 -> 67931.94 | K8: =Historical_Financials!C8 -> 75323.34 | L8: =Forecast_Model!D31 -> 80561 | M8: =Forecast_Model!E31 -> 86214 | N8: =Forecast_Model!F31 -> 92320
B9: creates regulatory and ESG valuation risk | H9: EBIT Margin | I9: =Historical_Financials!P6 -> 0.36244517 | J9: =Historical_Financials!P7 -> 0.37077596 | K9: =Historical_Financials!P8 -> 0.34304706 | L9: =Forecast_Model!D25 -> 0.33763881 | M9: =Forecast_Model!E25 -> 0.3350507 | N9: =Forecast_Model!F25 -> 0.332635
B10: 2. FMCG growing at 11% but EBIT margins at | H10: Adj. Earnings / NOPAT | I10: =Historical_Financials!H6 -> 19191.66 | J10: =Historical_Financials!H7 -> 20458.78 | K10: =Historical_Financials!H8 -> 19600 | L10: =Forecast_Model!D33 -> 20400.39 | M10: =Forecast_Model!E33 -> 21664.546 | N10: =Forecast_Model!F33 -> 23031.647
B11: ~8% vs HUL's 22% - re-rating requires margin | H11: FCFF | I11: =Historical_Financials!M6 -> 17541.253 | J11: =Historical_Financials!M7 -> 17012.1 | K11: =Historical_Financials!M8 -> 17259.741 | L11: =Forecast_Model!D37 -> 19651 | M11: =Forecast_Model!E37 -> 20862 | N11: =Forecast_Model!F37 -> 22171
B12: expansion not yet visible in cash flows | H12: P/E (x) | I12: - | J12: - | K12: =Relative_Valuation!D17 -> 20.130255 | L12: =Relative_Valuation!D5/Forecast_Model!D33 -> 19.340464 | M12: =Relative_Valuation!D5/Forecast_Model!E33 -> 18.211921 | N12: =Relative_Valuation!D5/Forecast_Model!F33 -> 17.130907
B13: 3. ITC trades at 20x P/E vs tobacco peers at | H13: EV/EBIT(x) | I13: - | J13: - | K13: =Relative_Valuation!E17 -> 15.117659 | L13: =Relative_Valuation!C17/Forecast_Model!D32 -> 14.361196 | M13: =Relative_Valuation!C17/Forecast_Model!E32 -> 13.523201 | N13: =Relative_Valuation!C17/Forecast_Model!F32 -> 12.720497
B14: 24x and FMCG peers at ~72x+ - conglomerate | H14: Note: Historical figures show Adjusted PAT; forecast figures show NOPAT (EBIT × 75%) as
B15: discount persists with no near-term catalyst | H15: interest expense is not explicitly modeled.
B16: 4. Hotels demerger removes earnings drag but
B17: makes cigarette profit dependency more
B18: pronounced going forward
B20: VALUATION SUMMARY | H20: SCENARIO ANALYSIS
B21: Method | C21: Implied Value | D21: Vs CMP | H21: Scenario | I21: Key Assumption | J21: Target Price
B22: DCF Base Case | C22: ='DCF (Formatted) '!H20 -> 254.73418 | D22: ='DCF (Formatted) '!J33 -> -0.18091904 | H22: Bear | I22: WACC 12%, g 3%, Slower FMCG | J22: ₹216
B23: Tobacco Comps P/E | C23: =Relative_Valuation!O18 -> 374.55234 | D23: +20% | H23: Base | I23: WACC 11.29%, g 4% | J23: ='DCF (Formatted) '!H20 -> 254.73418
B24: FMCG Comps P/E | C24: =Relative_Valuation!O19 -> 1120.1698 | D24: +260% | H24: Bull | I24: WACC 10%, g 5%, FMCG 13% | J24: ₹351
B25: CMP | C25: ='DCF (Formatted) '!J32 -> 311 | D25: - | H25: Even in bull case upside only ~13% from CMP - asymmetric
B26: FMCG implied ₹1,120 highlights ITC is not valued | H26: risk-reward, caution warranted
B27: as pure FMCG - tobacco discount is structural
B29: KEY RISKS
B30: Risk | C30: Description
B31: Regulatory | C31: Excise duty hikes on cigarettes compress margins and volumes instantly - ~78% EBIT dependency makes this existential
B32: Execution | C32: FMCG margin expansion uncertain — decade of investment with margins still at ~8% vs industry benchmark of 22%
B33: ESG | C33: Institutional and ESG funds increasingly exclude tobacco — structural ceiling on multiple expansion
B35: Verdict
B36: RECOMMENDATION: | C36: CAUTIOUS / HOLD
B37: Intrinsic Value: | C37: =J23 -> 254.73418 | D37: CMP: | E37: =C25 -> 311 | F37: Downside: | G37: =D22 -> -0.18091904
B38: Bull case upside (~13%) does not compensate for bear case downside (~30% to ₹217).
B39: Market appears to be partially pricing future FMCG scaling and margin expansion ahead of current fundamentals
